Workbook

Sheet Petunjuk
B1: Buku Kasus Uji dan QC: Aplikasi Belajar Bahasa Jepang
B2: 260 kasus uji, 111 fitur terpetakan. Dibuat 8 Oktober 2026 dari kode aplikasi dan hasil uji di lingkungan pengembangan; belum dijalankan di server penguji.
B4: 1. Untuk apa buku ini
B5: Tujuan | C5: Memandu penguji memeriksa aplikasi murid, aplikasi admin, dan API secara menyeluruh sebelum rilis, mencatat hasilnya, mencatat bug, dan memutuskan layak rilis atau tidak. Kasus yang juga dijalankan skrip otomatis ditandai di kolom Otomatis (lihat qa/README.md untuk cara menjalankannya); kasus lainnya dijalankan manual.
B6: Yang belum dicakup | C6: Kasus uji di sini disusun dari kode dan pengujian di lingkungan pengembangan dengan layanan AI tiruan. Mutu balasan AI sungguhan, suara sungguhan, email sungguhan, Safari/Firefox, dan ponsel sungguhan baru bisa dinilai oleh penguji. Hasil di server penguji bisa berbeda: catat setiap perbedaan.
B8: 2. Cara memakai (urutan yang disarankan)
B9: Langkah 1 | C9: Isi lembar Lingkungan (alamat, versi, akun uji). Siapkan akun uji sesuai qa/README.md.
B10: Langkah 2 | C10: Jalankan uji otomatis (npm run test:api, lalu npm test) dan catat hasilnya di lembar Ringkasan, blok "Hasil uji otomatis".
B11: Langkah 3 | C11: Kerjakan lembar Kasus Uji dari atas ke bawah, dahulukan prioritas P1. Isi kolom kuning: Hasil, Hasil aktual, ID Bug, Penguji, Tanggal, Perangkat.
B12: Langkah 4 | C12: Setiap kasus yang Gagal: catat di lembar Log Bug (satu baris per bug) dan tulis ID bug-nya di kolom ID Bug pada kasusnya.
B13: Langkah 5 | C13: Uji alur inti di beberapa perangkat dan browser, lalu isi lembar Perangkat.
B14: Langkah 6 | C14: Periksa isi pelajaran bersama pengajar (kasus TC-KT-*, berkas reports/konten dari npm run konten).
B15: Langkah 7 | C15: Sebelum rilis, kerjakan lembar QC Rilis dan isi keputusan akhir. Lembar Ringkasan menghitung sendiri angka-angkanya.
B17: 3. Warna dan kolom
B18: Kuning | C18: Sel yang DIISI penguji (Hasil, catatan, ID Bug, penguji, tanggal, perangkat, status, dan sebagainya).
B19: Abu-abu | C19: Sel hasil hitungan otomatis (rumus). Jangan diketik ulang.
B20: Putih | C20: Isi kasus uji dari tim (judul, langkah, hasil yang diharapkan). Bila langkah atau harapannya keliru, catat di kolom Catatan penguji dan kabari tim.
B22: 4. Arti status hasil kasus uji
B23: Lulus | C23: Semua langkah dijalankan dan hasilnya sama dengan Hasil yang diharapkan.
B24: Gagal | C24: Hasilnya berbeda dari yang diharapkan atau terjadi galat. Wajib dicatat di Log Bug.
B25: Diblokir | C25: Tidak bisa dijalankan karena hal lain (mis. layanan AI belum aktif, data belum siap). Tulis penyebabnya di Hasil aktual.
B26: Dilewati | C26: Sengaja tidak dijalankan pada putaran ini (mis. butuh perangkat yang tidak ada). Tulis alasannya.
B27: Belum diuji | C27: Bawaan: belum dijalankan.
B29: 5. Tingkat keparahan bug
B30: Kritis | C30: Aplikasi tidak bisa dipakai, data hilang/bocor, atau murid tidak bisa belajar sama sekali. Menghentikan rilis.
B31: Tinggi | C31: Fitur utama rusak atau hasilnya salah (mis. nilai/XP salah) dan tidak ada jalan pintas. Sebaiknya diperbaiki sebelum rilis.
B32: Sedang | C32: Fitur tidak berfungsi seperti seharusnya tetapi ada jalan pintas, atau berdampak pada sedikit pengguna.
B33: Rendah | C33: Kosmetik, salah ketik, atau gangguan kecil yang tidak menghalangi belajar.
B35: 6. Isi lembar
B36: Lingkungan | C36: Alamat, versi, pengaturan server, dan akun uji untuk putaran ini.
B37: Kasus Uji | C37: Seluruh kasus uji: langkah, hasil yang diharapkan, dan kolom isian hasil.
B38: Ringkasan | C38: Hitungan otomatis hasil per area dan prioritas, bug terbuka, serta rekomendasi sementara.
B39: Log Bug | C39: Daftar bug yang ditemukan.
B40: Perangkat | C40: Matriks alur inti per perangkat dan browser.
B41: QC Rilis | C41: Daftar periksa sebelum rilis dan keputusan akhir.
B42: Cakupan Fitur | C42: Pemetaan 111 fitur ke kasus uji; fitur yang tersedia tetapi tanpa kasus uji ditandai merah.
B43: Data Uji | C43: Contoh isian untuk uji batas, kalkulator ambang lulus, dan jumlah soal tiap pelajaran.
B44: Temuan Awal | C44: Hal yang ditemukan tim saat menyusun buku ini dan perlu keputusan. Bukan bug yang sudah dikonfirmasi di server penguji.
B46: 7. Contoh pengisian (hanya contoh, bukan data nyata)
B47: Kasus Uji | C47: ID TC-PL-10 | Hasil: Gagal | Hasil aktual: "Layar hasil menampilkan 2 bintang padahal 0 salah; XP +20 bukan +30" | ID Bug: BUG-003 | Penguji: Sari | Tanggal: 09/10/2026 | Perangkat: Pixel 7, Chrome 130
...

Sheet Lingkungan
A1: Lingkungan uji
A2: Isi sebelum mulai menguji. Kolom Contoh hanya memperlihatkan bentuk isian yang diharapkan.
A4: Hal | B4: Isian penguji | C4: Contoh (bukan data nyata) | D4: Keterangan
A5: Nama lingkungan | C5: Staging | D5: Server percobaan sebelum dipakai murid.
A6: Tanggal uji (mulai - selesai) | C6: 09/10/2026 - 11/10/2026
A7: Penguji utama | C7: Sari Wulandari
A8: Alamat aplikasi murid | C8: https://belajar.contoh.id | D8: Sama dengan QA_STUDENT_URL di qa/.env.
A9: Alamat aplikasi admin | C9: https://admin-belajar.contoh.id | D9: Sama dengan QA_ADMIN_URL.
A10: Alamat API | C10: https://belajar.contoh.id/api | D10: Sama dengan QA_API_URL. Di server produksi API diakses lewat awalan /api pada alamat aplikasi.
A11: Versi aplikasi (commit) | C11: b741aca | D11: Hasil perintah: git rev-parse --short HEAD di server atau repositori.
A12: Waktu deploy terakhir | C12: 08/10/2026 21:15
A13: Layanan AI aktif (kunci OpenAI)? | C13: Ya | D13: Ya/Tidak. Bila Tidak, kasus TC-AI-09 dan seterusnya diblokir.
A14: Suara (TTS) sudah dibuat? | C14: Tidak | D14: Perintah tts:seed. Bila Tidak, audio pelajaran/Kamus belum ada.
A15: Jatah AI harian (TUTOR_DAILY_QUOTA) | C15: 20 | D15: Turunkan (mis. 2) bila menguji jatah habis.
A16: Zona waktu server (TZ) | C16: Asia/Jakarta | D16: Menentukan pergantian hari streak, awal minggu peringkat, dan jatah AI.
A17: Pengiriman email aktif? | C17: Tidak (log saja) | D17: Saat ini email undangan/reset hanya dicatat di log API.
A18: Jumlah murid / kelas sebelum uji | C18: 8 murid / 13 kelas | D18: Dari lembar admin Murid dan Kelas.
A19: Versi Node.js dan Playwright | C19: Node 22.11, Playwright 1.56.1 | D19: Perintah: node -v dan npx playwright --version.
A20: Alat lain (browser, ponsel) | C20: Chrome 130, Pixel 7, iPhone 14 iOS 18 | D20: Detail perangkat dicatat juga di lembar Perangkat.
A22: Akun uji (JANGAN menulis password di berkas ini)
A23: Peran | B23: Email | C23: Contoh | D23: Dipakai untuk
A24: Murid uji utama (QA_STUDENT_*) | C24: qa-murid@example.com | D24: Semua uji murid dan uji otomatis; progres belajar akan terisi.
A25: Murid uji kedua (QA_STUDENT2_*) | C25: qa-murid2@example.com | D25: Uji yang mengubah akun: pindah kelas, nonaktifkan, reset password.
A26: Murid uji penguncian (QA_LOCKOUT_*) | C26: qa-murid-kunci@example.com | D26: HANYA uji penguncian akun; terkunci 15 menit sesudahnya.
A27: Admin uji (QA_ADMIN_*) | C27: qa-admin@example.com | D27: Semua uji admin.
A28: Murid baru (dari undangan) | C28: qa-baru-1@example.com | D28: Uji pendaftaran lewat undangan (TC-AK-01 dan seterusnya).

Sheet Kasus Uji
A1: Kasus uji
A2: Kolom kuning diisi penguji. Prioritas: P1 = kritis (alur inti dan keamanan), P2 = penting, P3 = pelengkap. Kolom Otomatis menunjukkan skrip yang menjalankan kasus yang sama; tetap isi Hasil sesuai laporan skrip atau hasil uji manual Anda.
A4: No | B4: ID | C4: Area | D4: Aplikasi | E4: Prioritas | F4: Judul kasus uji | G4: Prasyarat | H4: Langkah | I4: Hasil yang diharapkan | J4: Fitur terkait | K4: Otomatis | L4: Catatan dari tim | M4: Hasil | N4: Hasil aktual / catatan penguji | O4: ID Bug | P4: Penguji | Q4: Tanggal uji | R4: Perangkat / browser
A5: 1 | B5: TC-AK-01 | C5: Akun dan masuk | D5: Murid | E5: P1 | F5: Mendaftar lewat tautan undangan yang sah, sampai masuk ke Beranda | G5: Admin sudah membuat undangan untuk email uji yang belum pernah terdaftar. Tautan ada di catatan (log) API karena email belum terkirim otomatis; lihat qa/README.md bagian "Mengambil tautan undangan dan reset password". | H5: 1. Buka tautan undangan di browser. 2. Periksa layar: judul "Selamat datang" (ditambah nama lembaga bila ada), kolom Email sudah terisi. 3. Isi Nama lengkap, Password (contoh Murid2026) dan Konfirmasi password yang sama. 4. Tekan Buat Akun. 5. Selesaikan 3 layar sambutan sampai Mulai Belajar. 6. Di aplikasi admin, buka Undangan lalu Murid. | I5: Akun terbentuk dan murid langsung masuk (tidak diminta login lagi), terbuka layar sambutan "Langkah 1 dari 3". Setelah Mulai Belajar terbuka Beranda dengan nama dan kelas sesuai undangan. Di admin undangan berstatus Diterima dan murid muncul di daftar Murid, berstatus Aktif, XP 0. | J5: AK-01, AK-03, AK-09, UD-02 | K5: Tidak (manual) | M5: Belum diuji
A6: 2 | B6: TC-AK-02 | C6: Akun dan masuk | D6: Murid | E6: P1 | F6: Aturan password dan isian wajib di formulir pendaftaran | G6: Tautan undangan yang sah (belum dipakai). | H6: 1. Kosongkan Nama lengkap lalu tekan Buat Akun. 2. Isi nama, password "abc123" (7 karakter) dan konfirmasi sama; tekan Buat Akun. 3. Ganti password jadi "abcdefgh" (tanpa angka); tekan Buat Akun. 4. Ganti password jadi "12345678" (tanpa huruf); tekan Buat Akun. 5. Isi password "Murid2026" tetapi konfirmasi "Murid2027"; tekan Buat Akun. | I6: Tiap kesalahan memunculkan pesan merah yang jelas: "Nama lengkap wajib diisi.", "Password minimal 8 karakter.", "Password harus mengandung huruf dan angka." (dua kali), dan "Konfirmasi password tidak sama.". Petunjuk "Minimal 8 karakter, mengandung huruf dan angka." terlihat di dekat kolom. Tidak ada akun yang terbentuk. | J6: AK-01 | K6: Tidak (manual) | M6: Belum diuji
A7: 3 | B7: TC-AK-03 | C7: Akun dan masuk | D7: Murid | E7: P2 | F7: Email di formulir pendaftaran terkunci sesuai undangan | G7: Tautan undangan yang sah. | H7: 1. Buka tautan undangan. 2. Coba klik dan mengetik di kolom Email. | I7: Kolom Email sudah berisi email yang diundang, tidak bisa diubah, dan ada keterangan "Email terkunci sesuai undangan.". | J7: AK-01 | K7: Tidak (manual) | M7: Belum diuji
A8: 4 | B8: TC-AK-04 | C8: Akun dan masuk | D8: Murid | E8: P2 | F8: Tautan undangan yang tidak dikenal | G8: Tidak perlu masuk. | H8: 1. Buka /invite/token-ngawur di aplikasi murid. | I8: Judul "Tautan undangan tidak valid" dan penjelasan "Tautan ini tidak dikenali...". Tidak ada formulir pendaftaran. | J8: AK-02 | K8: Ya: murid-publik/akun-masuk.spec.ts | M8: Belum diuji
A9: 5 | B9: TC-AK-05 | C9: Akun dan masuk | D9: Murid | E9: P2 | F9: Undangan kedaluwarsa: pesan jelas dan permintaan undangan ulang dibatasi | G9: Satu undangan yang tautannya sudah disalin. Agar kedaluwarsa tanpa menunggu 7 hari, ubah masa berlakunya di database: UPDATE invitations SET expires_at = now() - interval '1 day' WHERE email = '<email uji>'; | H9: 1. Buka tautan undangan yang kedaluwarsa. 2. Tekan Minta undangan ulang. 3. Ulangi permintaan sampai 4 kali dalam satu jam. | I9: Judul "Undangan sudah kedaluwarsa" dan tombol Minta undangan ulang. Permintaan pertama sampai ketiga berhasil (pesan konfirmasi). Permintaan keempat dalam jam yang sama ditolak dengan pesan "Terlalu banyak percobaan. Coba lagi beberapa saat lagi.". Tidak ada formulir pendaftaran. | J9: AK-02 | K9: Tidak (manual) | L9: Butuh akses database untuk menyiapkan data. Batas 3 per jam dihitung per alamat IP, bukan per tautan: penguji di jaringan kantor yang sama berbagi batas ini. Email ke admin belum terkirim otomatis (AK-10), jadi hasilnya hanya terlihat di log API. | M9: Belum diuji
A10: 6 | B10: TC-AK-06 | C10: Akun dan masuk | D10: Murid | E10: P2 | F10: Undangan yang dicabut dan undangan yang sudah dipakai | G10: Satu undangan yang dicabut admin (status Dicabut) dan satu undangan yang sudah dipakai mendaftar (status Diterima); tautan keduanya sudah disalin. | H10: 1. Buka tautan undangan yang dicabut. 2. Buka tautan undangan yang sudah dipakai. | I10: Yang dicabut: "Undangan sudah dicabut" dengan anjuran hubungi admin. Yang sudah dipakai: "Undangan sudah dipakai" dengan anjuran masuk memakai email dan password yang dibuat. Tidak ada formulir pendaftaran di keduanya. | J10: AK-02 | K10: Tidak (manual) | M10: Belum diuji
A11: 7 | B11: TC-AK-07 | C11: Akun dan masuk | D11: Murid | E11: P2 | F11: Layar sambutan tiga langkah | G11: Sudah masuk. Buka /welcome (muncul otomatis setelah mendaftar). | H11: 1. Pada langkah 1, lihat tiga pilihan target XP (Santai 10, Reguler 30, Serius 50), pilih salah satu, tekan Lanjut. 2. Pada langkah 2 lihat level tempat belajar dimulai; tekan Lanjut. 3. Pada langkah 3 periksa ringkasan Kelas, Target harian, Level awal; tekan Kembali dua kali lalu Lanjut dua kali. 4. Tekan Mulai Belajar. | I11: Penunjuk "Langkah N dari 3" selalu benar, pilihan target tersimpan (cek di Profil), Kembali tidak menghilangkan pilihan, dan Mulai Belajar membuka Beranda. | J11: AK-03 | K11: Ya: murid/akun.spec.ts | M11: Belum diuji
A12: 8 | B12: TC-AK-08 | C12: Akun dan masuk | D12: Murid | E12: P1 | F12: Masuk dengan email dan password yang benar | G12: Akun murid uji aktif. | H12: 1. Buka aplikasi murid, halaman Masuk. 2. Isi Email dan Password. 3. Tekan Masuk. | I12: Terbuka Beranda dengan sapaan "Selamat datang, <nama>" dan tombol Keluar di menu. Tidak ada pesan galat. | J12: AK-04 | K12: Ya: murid-publik/akun-masuk.spec.ts | M12: Belum diuji
A13: 9 | B13: TC-AK-09 | C13: Akun dan masuk | D13: Murid | E13: P1 | F13: Password salah ditolak dengan pesan yang jelas | G13: Akun murid uji aktif (bukan akun khusus penguncian). | H13: 1. Isi email yang benar dan password yang salah. 2. Tekan Masuk. | I13: Muncul "Email atau password salah." dan murid tetap di halaman Masuk. | J13: AK-04 | K13: Ya: murid-publik/akun-masuk.spec.ts | M13: Belum diuji
A14: 10 | B14: TC-AK-10 | C14: Akun dan masuk | D14: Murid | E14: P1 | F14: Email yang tidak terdaftar mendapat pesan yang sama | G14: Tidak perlu akun. | H14: 1. Isi email acak yang belum terdaftar dan password sembarang. 2. Tekan Masuk. | I14: Pesan persis sama dengan password salah ("Email atau password salah."): aplikasi tidak membocorkan siapa yang terdaftar. | J14: AK-04 | K14: Ya: murid-publik/akun-masuk.spec.ts | M14: Belum diuji
A15: 11 | B15: TC-AK-11 | C15: Akun dan masuk | D15: Murid | E15: P2 | F15: Isian kosong atau email berformat salah tidak dikirim ke server | G15: Tidak perlu akun. | H15: 1. Tekan Masuk dengan semua kolom kosong. 2. Isi email "bukan-email" dan password "x", tekan Masuk. | I15: Browser menahan formulir dengan petunjuk bawaannya; tidak ada permintaan login ke server (periksa tab Network) dan tidak ada pesan galat server. | J15: AK-04 | K15: Ya: murid-publik/akun-masuk.spec.ts | M15: Belum diuji
A16: 12 | B16: TC-AK-12 | C16: Akun dan masuk | D16: Murid | E16: P1 | F16: Sesi bertahan setelah halaman dimuat ulang dan setelah pindah halaman | G16: Sudah masuk. | H16: 1. Tekan F5 di Beranda. 2. Buka Profil lewat menu, lalu kembali ke Beranda. | I16: Murid tetap masuk (tidak diminta login) dan Beranda tampil lengkap setelah dimuat ulang. | J16: AK-04 | K16: Ya: murid/akun.spec.ts | M16: Belum diuji
A17: 13 | B17: TC-AK-13 | C17: Akun dan masuk | D17: Murid | E17: P1 | F17: Halaman belajar tidak bisa dibuka tanpa masuk | G17: Belum masuk (keluar dulu atau pakai jendela penyamaran). | H17: 1. Buka satu per satu: /, /profile, /learn/l1, /conversation, /conversation/ngobrol-ai, /dictionary, /flashcards, /leaderboard, /welcome. | I17: Setiap alamat langsung mengarah ke layar Masuk. Tidak ada isi halaman belajar yang sempat terlihat. | J17: AK-04 | K17: Ya: murid-publik/akun-masuk.spec.ts | M17: Belum diuji
A18: 14 | B18: TC-AK-14 | C18: Akun dan masuk | D18: Murid | E18: P1 | F18: Akun admin tidak bisa masuk di aplikasi murid | G18: Punya akun admin. | H18: 1. Di halaman Masuk aplikasi murid, isi email dan password admin. 2. Tekan Masuk. | I18: "Email atau password salah." Akun admin dan akun murid adalah dua daftar yang terpisah. | J18: AK-04, AD-01 | K18: Ya: murid-publik/akun-masuk.spec.ts | M18: Belum diuji
A19: 15 | B19: TC-AK-15 | C19: Akun dan masuk | D19: Murid | E19: P1 | F19: Akun terkunci 15 menit setelah 5 kali salah password | G19: Pakai akun KHUSUS uji penguncian (QA_LOCKOUT_*). Setelah uji ini akun terkunci 15 menit, jangan pakai akun lain. | H19: 1. Masukkan password salah berulang sampai pesan berubah. 2. Setelah terkunci, masukkan password yang BENAR. 3. Tunggu 15 menit lalu masuk dengan password benar (opsional). | I19: Setelah kesalahan ke-5 muncul "Terlalu banyak percobaan gagal. Coba lagi dalam 15 menit." Password yang benar pun ditolak dengan pesan yang sama selama terkunci. Setelah 15 menit akun bisa masuk lagi. | J19: AK-05 | K19: Ya: murid-publik/akun-masuk.spec.ts | L19: Otomatis menguji sampai langkah 2. Langkah 3 hanya bisa dicek manual (menunggu). | M19: Belum diuji
A20: 16 | B20: TC-AK-16 | C20: Akun dan masuk | D20: Murid | E20: P1 | F20: Lupa password: jawaban sama untuk email terdaftar maupun tidak | G20: Tidak perlu masuk. | H20: 1. Di Masuk tekan Lupa password?. 2. Isi email yang tidak terdaftar, tekan Kirim Tautan Reset. 3. Ulangi dengan email murid uji yang terdaftar. | I20: Dua-duanya menampilkan layar "Cek Emailmu" dengan kalimat yang sama ("Kalau ... terdaftar, kami sudah mengirim tautan..." dan masa berlaku 1 jam). Aplikasi tidak membocorkan siapa yang terdaftar. | J20: AK-06 | K20: Ya: murid-publik/akun-masuk.spec.ts | L20: Catatan: kalimat "kami sudah mengirim tautan" tampil walau email belum benar-benar terkirim (AK-10). Pastikan email aktif sebelum rilis. | M20: Belum diuji
A21: 17 | B21: TC-AK-17 | C21: Akun dan masuk | D21: Murid | E21: P2 | F21: Batas 3 permintaan reset password per jam untuk satu email | G21: Akses ke log API (docker compose logs api). | H21: 1. Minta tautan reset untuk email murid uji 4 kali berturut-turut. 2. Setiap kali, catat tampilan layar dan baris "[STUB]" di log API. | I21: Layar selalu sama ("Cek Emailmu"), tetapi di log hanya tiga tautan yang tercatat; permintaan keempat dalam satu jam tidak membuat tautan baru. | J21: AK-06 | K21: Tidak (manual) | L21: Batas ini sengaja tidak terlihat di layar (anti pembocoran akun), jadi hanya bisa dibuktikan lewat log. | M21: Belum diuji
A22: 18 | B22: TC-AK-18 | C22: Akun dan masuk | D22: Murid | E22: P1 | F22: Membuat password baru lewat tautan reset sampai bisa masuk | G22: Tautan reset yang sah. Tautan ada di catatan (log) API karena email belum terkirim otomatis; lihat qa/README.md bagian "Mengambil tautan undangan dan reset password". | H22: 1. Buka tautan reset. 2. Isi Password baru dan Konfirmasi password baru (memenuhi aturan), tekan Simpan Password. 3. Di layar Masuk, perhatikan pesan, lalu masuk dengan password baru. 4. Coba masuk dengan password lama. | I22: Muncul "Password berhasil diubah. Silakan masuk dengan password barumu." Password baru berhasil masuk; password lama ditolak. | J22: AK-07 | K22: Tidak (manual) | M22: Belum diuji
A23: 19 | B23: TC-AK-19 | C23: Akun dan masuk | D23: Murid | E23: P2 | F23: Tautan reset yang tidak berlaku | G23: Tidak perlu masuk. | H23: 1. Buka /reset-password/token-ngawur. 2. Isi password baru dan konfirmasi, kirim formulir. | I23: Judul "Tautan Reset Tidak Berlaku", penjelasan bahwa tautan berlaku 1 jam dan satu kali pakai, serta tautan Minta Tautan Reset Baru. | J23: AK-07 | K23: Ya: murid-publik/akun-masuk.spec.ts | M23: Belum diuji
A24: 20 | B24: TC-AK-20 | C24: Akun dan masuk | D24: Murid | E24: P2 | F24: Tautan reset hanya bisa dipakai sekali dan kedaluwarsa setelah 1 jam | G24: Tautan reset yang sah dan sudah dipakai satu kali. | H24: 1. Buka lagi tautan yang sama dan coba ganti password. 2. (Opsional) Pakai tautan baru yang dibuat lebih dari 1 jam lalu (atau ubah expires_at di database). | I24: Tautan yang sudah dipakai maupun yang kedaluwarsa menampilkan "Tautan Reset Tidak Berlaku"; password tidak berubah. | J24: AK-07 | K24: Tidak (manual) | M24: Belum diuji
A25: 21 | B25: TC-AK-21 | C25: Akun dan masuk | D25: Murid | E25: P1 | F25: Keluar mengakhiri sesi di perangkat itu | G25: Sudah masuk. | H25: 1. Tekan Keluar di menu. 2. Tekan tombol kembali browser, lalu buka /learn/l1 secara langsung. | I25: Murid kembali ke layar Masuk. Halaman belajar tidak bisa dibuka lagi tanpa masuk, dan token masuk hilang dari penyimpanan browser. | J25: AK-08 | K25: Ya: murid/akun.spec.ts | M25: Belum diuji
A26: 22 | B26: TC-AK-22 | C26: Akun dan masuk | D26: Murid | E26: P2 | F26: Sesi bertahan setelah browser ditutup dan dibuka lagi | G26: Sudah masuk di browser biasa (bukan jendela penyamaran). | H26: 1. Tutup seluruh jendela browser. 2. Buka lagi dan langsung ke alamat aplikasi murid. | I26: Murid masih masuk dan Beranda terbuka tanpa mengetik password (sesi berlaku sampai 14 hari tidak dipakai). | J26: AK-04 | K26: Tidak (manual) | M26: Belum diuji
A27: 23 | B27: TC-AK-23 | C27: Akun dan masuk | D27: Semua | E27: P1 | F27: Murid yang dinonaktifkan admin: tidak bisa masuk, dan sesi yang sedang berjalan | G27: Murid uji kedua (QA_STUDENT2) dan akun admin. | H27: 1. Murid masuk di browser A dan biarkan terbuka. 2. Admin menonaktifkan murid itu (Murid, detail, Nonaktifkan Murid). 3. Murid mencoba masuk di browser B dengan password yang benar. 4. Di browser A, muat ulang halaman. 5. Admin mengaktifkan kembali; murid masuk lagi di browser B. | I27: Langkah 3: "Email atau password salah." (login baru diblokir). Langkah 5: murid bisa masuk lagi. Langkah 4 (yang diharapkan PRD: "murid tidak bisa login"): sebaiknya sesi A juga berhenti; perilaku saat ini sesi A tetap berjalan sampai token pembaruan habis (14 hari). | J27: MR-04, AK-04 | K27: Tidak (manual) | L27: Temuan diketahui di langkah 4; diuji otomatis di TC-AD-26 dan TC-AD-27 (yang kedua ditandai diharapkan gagal). Perlu keputusan pemilik produk. | M27: Belum diuji
A28: 24 | B28: TC-AK-24 | C28: Akun dan masuk | D28: API | E28: P2 | F28: Keluar hanya menghapus token di perangkat: token pembaruan lama masih berlaku | G28: Akses terminal dengan curl. Murid uji masuk di browser dan Anda bisa membaca refresh token di Application > Local Storage. | H28: 1. Salin nilai refresh token dari penyimpanan browser. 2. Tekan Keluar di aplikasi. 3. Kirim POST /auth/refresh dengan token yang disalin: curl -X POST <API>/auth/refresh -H 'content-type: application/json' -d '{"refreshToken":"<token>"}'. | I28: Yang diharapkan secara keamanan: 401 (sesi sudah dicabut di server). Perilaku saat ini: 200 dan token baru diberikan, karena Keluar belum memanggil server. | J28: AK-08 | K28: Tidak (manual) | L28: Temuan diketahui (tidak ada endpoint logout di API). Catat sebagai keputusan produk, bukan bug baru. | M28: Belum diuji
A29: 25 | B29: TC-AK-25 | C29: Akun dan masuk | D29: Murid | E29: P2 | F29: Mengganti password lewat reset memaksa masuk ulang di perangkat lain | G29: Murid uji masuk di dua browser (A dan B). | H29: 1. Di browser B minta tautan reset, ganti password. 2. Di browser A biarkan terbuka, tunggu sampai masa token akses habis (maks 1 jam) atau hapus access token dari penyimpanan lalu muat ulang. | I29: Di browser A sesi tidak bisa diperbarui lagi dan murid diarahkan ke layar Masuk. Password lama tidak berlaku. | J29: AK-07 | K29: Tidak (manual) | M29: Belum diuji
A30: 26 | B30: TC-AK-26 | C30: Akun dan masuk | D30: Murid | E30: P2 | F30: Reset password membuka kunci akun yang terkunci | G30: Akun uji penguncian sudah terkunci (5 kali salah). | H30: 1. Minta tautan reset untuk akun itu dan ganti password. 2. Masuk dengan password baru (sebelum 15 menit lewat). | I30: Murid bisa masuk dengan password baru walau belum 15 menit. | J30: AK-05, AK-07 | K30: Tidak (manual) | M30: Belum diuji
A31: 27 | B31: TC-AK-27 | C31: Akun dan masuk | D31: Murid | E31: P3 | F31: Gangguan jaringan saat masuk | G31: DevTools > Network > Offline (atau matikan Wi-Fi). | H31: 1. Isi email dan password yang benar. 2. Tekan Masuk. 3. Nyalakan jaringan lagi dan tekan Masuk. | I31: Muncul "Tidak dapat menghubungi server. Periksa koneksi internetmu lalu coba lagi.", tombol tidak macet di "Memproses...", dan setelah jaringan kembali masuk berhasil. | J31: AK-04 | K31: Tidak (manual) | M31: Belum diuji
A32: 28 | B32: TC-AK-28 | C32: Akun dan masuk | D32: Murid | E32: P3 | F32: Email tidak peka huruf besar-kecil dan spasi di ujung diabaikan | G32: Akun murid uji. | H32: 1. Masuk dengan email ditulis huruf besar semua (mis. QA-MURID@EXAMPLE.COM) dan ada spasi di akhir. | I32: Masuk berhasil. Penghitung percobaan gagal juga tidak terpecah per ejaan. | J32: AK-04 | K32: Tidak (manual) | M32: Belum diuji
A33: 29 | B33: TC-AK-29 | C33: Akun dan masuk | D33: Murid | E33: P3 | F33: Pengelola password browser | G33: Browser dengan pengelola password aktif (Chrome, Safari, Firefox). | H33: 1. Masuk dan setujui tawaran menyimpan password. 2. Keluar lalu buka halaman Masuk lagi. | I33: Browser menawarkan menyimpan dan mengisi email serta password; kolom dikenali sebagai email dan password. | J33: AK-04 | K33: Tidak (manual) | M33: Belum diuji
A34: 30 | B34: TC-AK-30 | C34: Akun dan masuk | D34: Murid | E34: P3 | F34: Dua tab: keluar di satu tab, tab lain tidak macet | G34: Sudah masuk di dua tab. | H34: 1. Di tab 2 tekan Keluar. 2. Di tab 1 buka halaman lain (mis. Kamus) dan lakukan satu pencarian. | I34: Tab 1 tidak berhenti dengan layar kosong. Murid diarahkan ke Masuk atau diberi pesan yang jelas, tanpa teks galat teknis. | J34: AK-08 | K34: Tidak (manual) | M34: Belum diuji
A35: 31 | B35: TC-AK-31 | C35: Akun dan masuk | D35: Semua | E35: P1 | F35: Email undangan dan reset password belum terkirim otomatis: tautan hanya ada di log server | G35: Akses ke log API (docker compose logs api) dan sebuah kotak email uji. | H35: 1. Admin membuat undangan untuk email uji, lalu minta tautan reset password untuk murid uji. 2. Periksa kotak masuk email penerima (juga folder spam). 3. Periksa log API: cari baris yang diawali "[STUB]". | I35: Kondisi saat ini (sudah diketahui): TIDAK ada email yang masuk; di log tercatat "[STUB] Undangan ke ... <tautan>" dan "[STUB] Reset password ke ... <tautan>". Sebelum dipakai murid sungguhan, tim harus memutuskan: menyambungkan penyedia email, atau menyalin tautan dari log lalu mengirimnya secara manual. | J35: AK-10, UD-01, UD-03, AK-06 | K35: Tidak (manual) | L35: Temuan diketahui, bukan bug baru. Item terkait ada di lembar QC Rilis. Tautan ada di catatan (log) API karena email belum terkirim otomatis; lihat qa/README.md bagian "Mengambil tautan undangan dan reset password". | M35: Belum diuji
A36: 32 | B36: TC-BR-01 | C36: Beranda dan jalur belajar | D36: Murid | E36: P1 | F36: Beranda menyapa murid dan menampilkan statistik belajar | G36: Sudah masuk. | H36: 1. Buka Beranda. | I36: Sapaan "Selamat datang, <nama>", kartu Streak (hari), Terpanjang (hari), dan "Pelajaran selesai N/M" dengan bilah kemajuan; tidak ada teks mentah seperti undefined atau NaN. | J36: BR-01 | K36: Ya: murid/beranda.spec.ts | M36: Belum diuji
A37: 33 | B37: TC-BR-02 | C37: Beranda dan jalur belajar | D37: Murid | E37: P1 | F37: Jalur belajar memuat unit dan pelajaran dengan keterangan status | G37: Sudah masuk. | H37: 1. Gulir seluruh Beranda. | I37: Ada judul level (Hiragana, N4), spanduk tiap unit, dan bulatan pelajaran. Tiap pelajaran bisa dibaca statusnya oleh pembaca layar: terkunci, tersedia, atau selesai (beserta bintang). | J37: BR-03 | K37: Ya: murid/beranda.spec.ts | M37: Belum diuji
A38: 34 | B38: TC-BR-03 | C38: Beranda dan jalur belajar | D38: Murid | E38: P1 | F38: Tombol Lanjutkan Belajar membuka pelajaran berikutnya | G38: Ada pelajaran yang belum selesai. | H38: 1. Tekan Lanjutkan Belajar di kartu sambutan. | I38: Terbuka pelajaran pertama yang masih tersedia (murid baru: Baris a, ka, sa) dengan tombol Tutup pelajaran di pojok. | J38: BR-02 | K38: Ya: murid/beranda.spec.ts | M38: Belum diuji
A39: 35 | B39: TC-BR-04 | C39: Beranda dan jalur belajar | D39: Murid | E39: P1 | F39: Pelajaran terkunci tidak bisa diklik | G39: Murid baru (hanya pelajaran pertama terbuka). | H39: 1. Klik pelajaran berikon gembok. 2. Arahkan kursor ke pelajaran terkunci. | I39: Tidak terjadi apa-apa (tetap di Beranda), kursor menunjukkan tidak boleh, dan tooltip "Terkunci". | J39: BR-04 | K39: Ya: murid/beranda.spec.ts | M39: Belum diuji
A40: 36 | B40: TC-BR-05 | C40: Beranda dan jalur belajar | D40: Murid | E40: P2 | F40: Pelajaran terkunci dibuka lewat alamat langsung: hasilnya ditolak server | G40: Murid baru; pelajaran Youon 2, sokuon, dan vokal panjang (l7) masih terkunci. | H40: 1. Buka /learn/l7 langsung di browser. 2. Kerjakan pelajaran sampai soal terakhir. 3. Kembali ke Beranda. | I40: Isi pelajaran tetap tampil (hanya pengiriman hasil yang dijaga server), tetapi di akhir muncul "Gagal mengirim hasil belajar." dan tombol Kembali ke Beranda. Pelajaran tetap terkunci, jumlah "Pelajaran selesai" tidak berubah, tidak ada XP. | J40: BR-04 | K40: Ya: murid/beranda.spec.ts | L40: Perilaku yang dirancang: server menjadi penegak kunci. Catat bila tim ingin layar pelajaran juga menolak dibuka. | M40: Belum diuji
A41: 37 | B41: TC-BR-06 | C41: Beranda dan jalur belajar | D41: Murid | E41: P2 | F41: Alamat pelajaran yang tidak ada | G41: Sudah masuk. | H41: 1. Buka /learn/tidak-ada. | I41: Pesan "Gagal memuat pelajaran." dan tombol Kembali ke Beranda; bukan layar kosong. | J41: BR-03 | K41: Ya: murid/beranda.spec.ts | M41: Belum diuji
...

Sheet Ringkasan
A1: Ringkasan hasil
A2: Semua angka di lembar ini dihitung otomatis dari lembar Kasus Uji dan Log Bug. Satu-satunya isian manual: blok "Hasil uji otomatis".
A4: Per area
A5: Area | B5: Total kasus | C5: Lulus | D5: Gagal | E5: Diblokir | F5: Dilewati | G5: Belum diuji | H5: % sudah diuji | I5: % lulus
A6: Akun dan masuk | B6: =COUNTIFS('Kasus Uji'!$C$5:$C$264,$A6) -> 31 | C6: =COUNTIFS('Kasus Uji'!$C$5:$C$264,$A6,'Kasus Uji'!$M$5:$M$264,"Lulus") -> 0 | D6: =COUNTIFS('Kasus Uji'!$C$5:$C$264,$A6,'Kasus Uji'!$M$5:$M$264,"Gagal") -> 0 | E6: =COUNTIFS('Kasus Uji'!$C$5:$C$264,$A6,'Kasus Uji'!$M$5:$M$264,"Diblokir") -> 0 | F6: =COUNTIFS('Kasus Uji'!$C$5:$C$264,$A6,'Kasus Uji'!$M$5:$M$264,"Dilewati") -> 0 | G6: =B6-C6-D6-E6-F6 -> 31 | H6: =IF(B6=0,0,(C6+D6)/B6) -> 0 | I6: =IF((C6+D6)=0,0,C6/(C6+D6)) -> 0
A7: Beranda dan jalur belajar | B7: =COUNTIFS('Kasus Uji'!$C$5:$C$264,$A7) -> 16 | C7: =COUNTIFS('Kasus Uji'!$C$5:$C$264,$A7,'Kasus Uji'!$M$5:$M$264,"Lulus") -> 0 | D7: =COUNTIFS('Kasus Uji'!$C$5:$C$264,$A7,'Kasus Uji'!$M$5:$M$264,"Gagal") -> 0 | E7: =COUNTIFS('Kasus Uji'!$C$5:$C$264,$A7,'Kasus Uji'!$M$5:$M$264,"Diblokir") -> 0 | F7: =COUNTIFS('Kasus Uji'!$C$5:$C$264,$A7,'Kasus Uji'!$M$5:$M$264,"Dilewati") -> 0 | G7: =B7-C7-D7-E7-F7 -> 16 | H7: =IF(B7=0,0,(C7+D7)/B7) -> 0 | I7: =IF((C7+D7)=0,0,C7/(C7+D7)) -> 0
A8: Pelajaran dan soal | B8: =COUNTIFS('Kasus Uji'!$C$5:$C$264,$A8) -> 21 | C8: =COUNTIFS('Kasus Uji'!$C$5:$C$264,$A8,'Kasus Uji'!$M$5:$M$264,"Lulus") -> 0 | D8: =COUNTIFS('Kasus Uji'!$C$5:$C$264,$A8,'Kasus Uji'!$M$5:$M$264,"Gagal") -> 0 | E8: =COUNTIFS('Kasus Uji'!$C$5:$C$264,$A8,'Kasus Uji'!$M$5:$M$264,"Diblokir") -> 0 | F8: =COUNTIFS('Kasus Uji'!$C$5:$C$264,$A8,'Kasus Uji'!$M$5:$M$264,"Dilewati") -> 0 | G8: =B8-C8-D8-E8-F8 -> 21 | H8: =IF(B8=0,0,(C8+D8)/B8) -> 0 | I8: =IF((C8+D8)=0,0,C8/(C8+D8)) -> 0
A9: Nilai, bintang, XP, streak | B9: =COUNTIFS('Kasus Uji'!$C$5:$C$264,$A9) -> 6 | C9: =COUNTIFS('Kasus Uji'!$C$5:$C$264,$A9,'Kasus Uji'!$M$5:$M$264,"Lulus") -> 0 | D9: =COUNTIFS('Kasus Uji'!$C$5:$C$264,$A9,'Kasus Uji'!$M$5:$M$264,"Gagal") -> 0 | E9: =COUNTIFS('Kasus Uji'!$C$5:$C$264,$A9,'Kasus Uji'!$M$5:$M$264,"Diblokir") -> 0 | F9: =COUNTIFS('Kasus Uji'!$C$5:$C$264,$A9,'Kasus Uji'!$M$5:$M$264,"Dilewati") -> 0 | G9: =B9-C9-D9-E9-F9 -> 6 | H9: =IF(B9=0,0,(C9+D9)/B9) -> 0 | I9: =IF((C9+D9)=0,0,C9/(C9+D9)) -> 0
A10: Percakapan (skenario) | B10: =COUNTIFS('Kasus Uji'!$C$5:$C$264,$A10) -> 15 | C10: =COUNTIFS('Kasus Uji'!$C$5:$C$264,$A10,'Kasus Uji'!$M$5:$M$264,"Lulus") -> 0 | D10: =COUNTIFS('Kasus Uji'!$C$5:$C$264,$A10,'Kasus Uji'!$M$5:$M$264,"Gagal") -> 0 | E10: =COUNTIFS('Kasus Uji'!$C$5:$C$264,$A10,'Kasus Uji'!$M$5:$M$264,"Diblokir") -> 0 | F10: =COUNTIFS('Kasus Uji'!$C$5:$C$264,$A10,'Kasus Uji'!$M$5:$M$264,"Dilewati") -> 0 | G10: =B10-C10-D10-E10-F10 -> 15 | H10: =IF(B10=0,0,(C10+D10)/B10) -> 0 | I10: =IF((C10+D10)=0,0,C10/(C10+D10)) -> 0
A11: Ngobrol dengan AI | B11: =COUNTIFS('Kasus Uji'!$C$5:$C$264,$A11) -> 27 | C11: =COUNTIFS('Kasus Uji'!$C$5:$C$264,$A11,'Kasus Uji'!$M$5:$M$264,"Lulus") -> 0 | D11: =COUNTIFS('Kasus Uji'!$C$5:$C$264,$A11,'Kasus Uji'!$M$5:$M$264,"Gagal") -> 0 | E11: =COUNTIFS('Kasus Uji'!$C$5:$C$264,$A11,'Kasus Uji'!$M$5:$M$264,"Diblokir") -> 0 | F11: =COUNTIFS('Kasus Uji'!$C$5:$C$264,$A11,'Kasus Uji'!$M$5:$M$264,"Dilewati") -> 0 | G11: =B11-C11-D11-E11-F11 -> 27 | H11: =IF(B11=0,0,(C11+D11)/B11) -> 0 | I11: =IF((C11+D11)=0,0,C11/(C11+D11)) -> 0
A12: Kamus | B12: =COUNTIFS('Kasus Uji'!$C$5:$C$264,$A12) -> 10 | C12: =COUNTIFS('Kasus Uji'!$C$5:$C$264,$A12,'Kasus Uji'!$M$5:$M$264,"Lulus") -> 0 | D12: =COUNTIFS('Kasus Uji'!$C$5:$C$264,$A12,'Kasus Uji'!$M$5:$M$264,"Gagal") -> 0 | E12: =COUNTIFS('Kasus Uji'!$C$5:$C$264,$A12,'Kasus Uji'!$M$5:$M$264,"Diblokir") -> 0 | F12: =COUNTIFS('Kasus Uji'!$C$5:$C$264,$A12,'Kasus Uji'!$M$5:$M$264,"Dilewati") -> 0 | G12: =B12-C12-D12-E12-F12 -> 10 | H12: =IF(B12=0,0,(C12+D12)/B12) -> 0 | I12: =IF((C12+D12)=0,0,C12/(C12+D12)) -> 0
A13: Flashcard | B13: =COUNTIFS('Kasus Uji'!$C$5:$C$264,$A13) -> 6 | C13: =COUNTIFS('Kasus Uji'!$C$5:$C$264,$A13,'Kasus Uji'!$M$5:$M$264,"Lulus") -> 0 | D13: =COUNTIFS('Kasus Uji'!$C$5:$C$264,$A13,'Kasus Uji'!$M$5:$M$264,"Gagal") -> 0 | E13: =COUNTIFS('Kasus Uji'!$C$5:$C$264,$A13,'Kasus Uji'!$M$5:$M$264,"Diblokir") -> 0 | F13: =COUNTIFS('Kasus Uji'!$C$5:$C$264,$A13,'Kasus Uji'!$M$5:$M$264,"Dilewati") -> 0 | G13: =B13-C13-D13-E13-F13 -> 6 | H13: =IF(B13=0,0,(C13+D13)/B13) -> 0 | I13: =IF((C13+D13)=0,0,C13/(C13+D13)) -> 0
A14: Leaderboard | B14: =COUNTIFS('Kasus Uji'!$C$5:$C$264,$A14) -> 5 | C14: =COUNTIFS('Kasus Uji'!$C$5:$C$264,$A14,'Kasus Uji'!$M$5:$M$264,"Lulus") -> 0 | D14: =COUNTIFS('Kasus Uji'!$C$5:$C$264,$A14,'Kasus Uji'!$M$5:$M$264,"Gagal") -> 0 | E14: =COUNTIFS('Kasus Uji'!$C$5:$C$264,$A14,'Kasus Uji'!$M$5:$M$264,"Diblokir") -> 0 | F14: =COUNTIFS('Kasus Uji'!$C$5:$C$264,$A14,'Kasus Uji'!$M$5:$M$264,"Dilewati") -> 0 | G14: =B14-C14-D14-E14-F14 -> 5 | H14: =IF(B14=0,0,(C14+D14)/B14) -> 0 | I14: =IF((C14+D14)=0,0,C14/(C14+D14)) -> 0
A15: Profil | B15: =COUNTIFS('Kasus Uji'!$C$5:$C$264,$A15) -> 8 | C15: =COUNTIFS('Kasus Uji'!$C$5:$C$264,$A15,'Kasus Uji'!$M$5:$M$264,"Lulus") -> 0 | D15: =COUNTIFS('Kasus Uji'!$C$5:$C$264,$A15,'Kasus Uji'!$M$5:$M$264,"Gagal") -> 0 | E15: =COUNTIFS('Kasus Uji'!$C$5:$C$264,$A15,'Kasus Uji'!$M$5:$M$264,"Diblokir") -> 0 | F15: =COUNTIFS('Kasus Uji'!$C$5:$C$264,$A15,'Kasus Uji'!$M$5:$M$264,"Dilewati") -> 0 | G15: =B15-C15-D15-E15-F15 -> 8 | H15: =IF(B15=0,0,(C15+D15)/B15) -> 0 | I15: =IF((C15+D15)=0,0,C15/(C15+D15)) -> 0
A16: Tampilan ponsel dan layar | B16: =COUNTIFS('Kasus Uji'!$C$5:$C$264,$A16) -> 18 | C16: =COUNTIFS('Kasus Uji'!$C$5:$C$264,$A16,'Kasus Uji'!$M$5:$M$264,"Lulus") -> 0 | D16: =COUNTIFS('Kasus Uji'!$C$5:$C$264,$A16,'Kasus Uji'!$M$5:$M$264,"Gagal") -> 0 | E16: =COUNTIFS('Kasus Uji'!$C$5:$C$264,$A16,'Kasus Uji'!$M$5:$M$264,"Diblokir") -> 0 | F16: =COUNTIFS('Kasus Uji'!$C$5:$C$264,$A16,'Kasus Uji'!$M$5:$M$264,"Dilewati") -> 0 | G16: =B16-C16-D16-E16-F16 -> 18 | H16: =IF(B16=0,0,(C16+D16)/B16) -> 0 | I16: =IF((C16+D16)=0,0,C16/(C16+D16)) -> 0
A17: Aksesibilitas | B17: =COUNTIFS('Kasus Uji'!$C$5:$C$264,$A17) -> 9 | C17: =COUNTIFS('Kasus Uji'!$C$5:$C$264,$A17,'Kasus Uji'!$M$5:$M$264,"Lulus") -> 0 | D17: =COUNTIFS('Kasus Uji'!$C$5:$C$264,$A17,'Kasus Uji'!$M$5:$M$264,"Gagal") -> 0 | E17: =COUNTIFS('Kasus Uji'!$C$5:$C$264,$A17,'Kasus Uji'!$M$5:$M$264,"Diblokir") -> 0 | F17: =COUNTIFS('Kasus Uji'!$C$5:$C$264,$A17,'Kasus Uji'!$M$5:$M$264,"Dilewati") -> 0 | G17: =B17-C17-D17-E17-F17 -> 9 | H17: =IF(B17=0,0,(C17+D17)/B17) -> 0 | I17: =IF((C17+D17)=0,0,C17/(C17+D17)) -> 0
... A22: Keamanan, kinerja, pemulihan | B22: =COUNTIFS('Kasus Uji'!$C$5:$C$264,$A22) -> 15 | C22: =COUNTIFS('Kasus Uji'!$C$5:$C$264,$A22,'Kasus Uji'!$M$5:$M$264,"Lulus") -> 0 | D22: =COUNTIFS('Kasus Uji'!$C$5:$C$264,$A22,'Kasus Uji'!$M$5:$M$264,"Gagal") -> 0 | E22: =COUNTIFS('Kasus Uji'!$C$5:$C$264,$A22,'Kasus Uji'!$M$5:$M$264,"Diblokir") -> 0 | F22: =COUNTIFS('Kasus Uji'!$C$5:$C$264,$A22,'Kasus Uji'!$M$5:$M$264,"Dilewati") -> 0 | G22: =B22-C22-D22-E22-F22 -> 15 | H22: =IF(B22=0,0,(C22+D22)/B22) -> 0 | I22: =IF((C22+D22)=0,0,C22/(C22+D22)) -> 0
A23: Jumlah | B23: =SUM(B6:B22) -> 260 | C23: =SUM(C6:C22) -> 0 | D23: =SUM(D6:D22) -> 0 | E23: =SUM(E6:E22) -> 0 | F23: =SUM(F6:F22) -> 0 | G23: =SUM(G6:G22) -> 260 | H23: =IF(B23=0,0,(C23+D23)/B23) -> 0 | I23: =IF((C23+D23)=0,0,C23/(C23+D23)) -> 0
A26: Per prioritas
A27: Prioritas | B27: Total kasus | C27: Lulus | D27: Gagal | E27: Diblokir | F27: Dilewati | G27: Belum diuji | H27: % sudah diuji | I27: % lulus
A28: P1 | B28: =COUNTIFS('Kasus Uji'!$E$5:$E$264,$A28) -> 111 | C28: =COUNTIFS('Kasus Uji'!$E$5:$E$264,$A28,'Kasus Uji'!$M$5:$M$264,"Lulus") -> 0 | D28: =COUNTIFS('Kasus Uji'!$E$5:$E$264,$A28,'Kasus Uji'!$M$5:$M$264,"Gagal") -> 0 | E28: =COUNTIFS('Kasus Uji'!$E$5:$E$264,$A28,'Kasus Uji'!$M$5:$M$264,"Diblokir") -> 0 | F28: =COUNTIFS('Kasus Uji'!$E$5:$E$264,$A28,'Kasus Uji'!$M$5:$M$264,"Dilewati") -> 0 | G28: =B28-C28-D28-E28-F28 -> 111 | H28: =IF(B28=0,0,(C28+D28)/B28) -> 0 | I28: =IF((C28+D28)=0,0,C28/(C28+D28)) -> 0 | J28: P1 = kritis
A29: P2 | B29: =COUNTIFS('Kasus Uji'!$E$5:$E$264,$A29) -> 99 | C29: =COUNTIFS('Kasus Uji'!$E$5:$E$264,$A29,'Kasus Uji'!$M$5:$M$264,"Lulus") -> 0 | D29: =COUNTIFS('Kasus Uji'!$E$5:$E$264,$A29,'Kasus Uji'!$M$5:$M$264,"Gagal") -> 0 | E29: =COUNTIFS('Kasus Uji'!$E$5:$E$264,$A29,'Kasus Uji'!$M$5:$M$264,"Diblokir") -> 0 | F29: =COUNTIFS('Kasus Uji'!$E$5:$E$264,$A29,'Kasus Uji'!$M$5:$M$264,"Dilewati") -> 0 | G29: =B29-C29-D29-E29-F29 -> 99 | H29: =IF(B29=0,0,(C29+D29)/B29) -> 0 | I29: =IF((C29+D29)=0,0,C29/(C29+D29)) -> 0 | J29: P2 = penting
A30: P3 | B30: =COUNTIFS('Kasus Uji'!$E$5:$E$264,$A30) -> 50 | C30: =COUNTIFS('Kasus Uji'!$E$5:$E$264,$A30,'Kasus Uji'!$M$5:$M$264,"Lulus") -> 0 | D30: =COUNTIFS('Kasus Uji'!$E$5:$E$264,$A30,'Kasus Uji'!$M$5:$M$264,"Gagal") -> 0 | E30: =COUNTIFS('Kasus Uji'!$E$5:$E$264,$A30,'Kasus Uji'!$M$5:$M$264,"Diblokir") -> 0 | F30: =COUNTIFS('Kasus Uji'!$E$5:$E$264,$A30,'Kasus Uji'!$M$5:$M$264,"Dilewati") -> 0 | G30: =B30-C30-D30-E30-F30 -> 50 | H30: =IF(B30=0,0,(C30+D30)/B30) -> 0 | I30: =IF((C30+D30)=0,0,C30/(C30+D30)) -> 0 | J30: P3 = pelengkap
A31: Jumlah | B31: =SUM(B28:B30) -> 260 | C31: =SUM(C28:C30) -> 0 | D31: =SUM(D28:D30) -> 0 | E31: =SUM(E28:E30) -> 0 | F31: =SUM(F28:F30) -> 0 | G31: =SUM(G28:G30) -> 260 | H31: =IF(B31=0,0,(C31+D31)/B31) -> 0 | I31: =IF((C31+D31)=0,0,C31/(C31+D31)) -> 0
A34: Indikator rilis
A35: Indikator | B35: Nilai
A36: Kasus P1 yang Gagal | B36: =D28 -> 0
A37: Kasus P1 yang belum selesai (Belum diuji, Diblokir, Dilewati) | B37: =B28-C28-D28 -> 111
A38: Bug Kritis terbuka | B38: =COUNTIFS('Log Bug'!$J$5:$J$154,"Kritis",'Log Bug'!$O$5:$O$154,"<>Ditutup",'Log Bug'!$O$5:$O$154,"<>Ditolak",'Log Bug'!$O$5:$O$154,"<>Ditunda") -> 0
A39: Bug Tinggi terbuka | B39: =COUNTIFS('Log Bug'!$J$5:$J$154,"Tinggi",'Log Bug'!$O$5:$O$154,"<>Ditutup",'Log Bug'!$O$5:$O$154,"<>Ditolak",'Log Bug'!$O$5:$O$154,"<>Ditunda") -> 0
A40: Rekomendasi sementara (bukan keputusan) | B40: =IF(B36>0,"BELUM LAYAK: ada kasus P1 yang gagal",IF(B38>0,"BELUM LAYAK: ada bug Kritis terbuka",IF(B37>0,"PENGUJIAN BELUM LENGKAP: kasus P1 belum selesai",IF(B39>0,"LAYAK DENGAN CATATAN: masih ada bug Tinggi terbuka","LAYAK secara pengujian: lanjutkan ke lembar QC Rilis")))) -> PENGUJIAN BELUM LENGKAP: kasus P1 belum selesai
A43: Bug menurut keparahan
A44: Keparahan | B44: Total | C44: Terbuka | D44: Selesai atau ditolak
A45: Kritis | B45: =COUNTIFS('Log Bug'!$J$5:$J$154,$A45) -> 0 | C45: =COUNTIFS('Log Bug'!$J$5:$J$154,$A45,'Log Bug'!$O$5:$O$154,"<>Ditutup",'Log Bug'!$O$5:$O$154,"<>Ditolak",'Log Bug'!$O$5:$O$154,"<>Ditunda") -> 0 | D45: =B45-C45 -> 0
A46: Tinggi | B46: =COUNTIFS('Log Bug'!$J$5:$J$154,$A46) -> 0 | C46: =COUNTIFS('Log Bug'!$J$5:$J$154,$A46,'Log Bug'!$O$5:$O$154,"<>Ditutup",'Log Bug'!$O$5:$O$154,"<>Ditolak",'Log Bug'!$O$5:$O$154,"<>Ditunda") -> 0 | D46: =B46-C46 -> 0
A47: Sedang | B47: =COUNTIFS('Log Bug'!$J$5:$J$154,$A47) -> 0 | C47: =COUNTIFS('Log Bug'!$J$5:$J$154,$A47,'Log Bug'!$O$5:$O$154,"<>Ditutup",'Log Bug'!$O$5:$O$154,"<>Ditolak",'Log Bug'!$O$5:$O$154,"<>Ditunda") -> 0 | D47: =B47-C47 -> 0
A48: Rendah | B48: =COUNTIFS('Log Bug'!$J$5:$J$154,$A48) -> 0 | C48: =COUNTIFS('Log Bug'!$J$5:$J$154,$A48,'Log Bug'!$O$5:$O$154,"<>Ditutup",'Log Bug'!$O$5:$O$154,"<>Ditolak",'Log Bug'!$O$5:$O$154,"<>Ditunda") -> 0 | D48: =B48-C48 -> 0
A49: Jumlah | B49: =SUM(B45:B48) -> 0 | C49: =SUM(C45:C48) -> 0 | D49: =SUM(D45:D48) -> 0
A52: Hasil uji otomatis (isi dari laporan skrip)
A53: Skrip | B53: Total | C53: Lulus | D53: Gagal | E53: Dilewati | F53: Tanggal | G53: % lulus
...

Sheet Log Bug
A1: Log bug
A2: Satu baris per bug. Isi sebanyak mungkin kolom kuning; sertakan tangkapan layar (nama berkasnya di kolom Lampiran). Contoh pengisian ada di lembar Petunjuk.
A4: ID Bug | B4: Tanggal | C4: Pelapor | D4: ID kasus uji | E4: Aplikasi | F4: Judul singkat | G4: Langkah mereproduksi | H4: Hasil yang seharusnya | I4: Hasil aktual | J4: Keparahan | K4: Prioritas perbaikan | L4: Perangkat / browser | M4: Lingkungan / versi | N4: Lampiran (nama berkas) | O4: Status | P4: Penanggung jawab | Q4: Catatan tim teknis
A5: BUG-001
A6: BUG-002
A7: BUG-003
A8: BUG-004
A9: BUG-005
A10: BUG-006
A11: BUG-007
A12: BUG-008
A13: BUG-009
A14: BUG-010
A15: BUG-011
A16: BUG-012
... A154: BUG-150

Sheet Perangkat
A1: Perangkat dan browser
A2: Uji alur inti di tiap perangkat dan browser yang dipakai murid. Skrip otomatis hanya mencakup Chromium (Chrome/Edge) dan emulasi ponsel; Safari, Firefox, dan ponsel sungguhan wajib diuji manual. Kolom Admin hanya untuk perangkat komputer.
A4: Perangkat / sistem operasi | B4: Browser dan versi | C4: Masuk dan keluar | D4: Beranda | E4: Pelajaran sampai hasil | F4: Percakapan (skenario) | G4: Ngobrol AI (ketik) | H4: Ngobrol AI (suara) | I4: Kamus | J4: Flashcard | K4: Leaderboard | L4: Profil | M4: Admin | N4: Catatan | O4: Penguji | P4: Tanggal
A5: Windows 11 | B5: Chrome (terbaru) | C5: Tidak diuji | D5: Tidak diuji | E5: Tidak diuji | F5: Tidak diuji | G5: Tidak diuji | H5: Tidak diuji | I5: Tidak diuji | J5: Tidak diuji | K5: Tidak diuji | L5: Tidak diuji | M5: Tidak diuji
A6: Windows 11 | B6: Edge (terbaru) | C6: Tidak diuji | D6: Tidak diuji | E6: Tidak diuji | F6: Tidak diuji | G6: Tidak diuji | H6: Tidak diuji | I6: Tidak diuji | J6: Tidak diuji | K6: Tidak diuji | L6: Tidak diuji | M6: Tidak diuji
A7: Windows 11 | B7: Firefox (terbaru) | C7: Tidak diuji | D7: Tidak diuji | E7: Tidak diuji | F7: Tidak diuji | G7: Tidak diuji | H7: Tidak diuji | I7: Tidak diuji | J7: Tidak diuji | K7: Tidak diuji | L7: Tidak diuji | M7: Tidak diuji
A8: macOS | B8: Safari (terbaru) | C8: Tidak diuji | D8: Tidak diuji | E8: Tidak diuji | F8: Tidak diuji | G8: Tidak diuji | H8: Tidak diuji | I8: Tidak diuji | J8: Tidak diuji | K8: Tidak diuji | L8: Tidak diuji | M8: Tidak diuji
A9: macOS | B9: Chrome (terbaru) | C9: Tidak diuji | D9: Tidak diuji | E9: Tidak diuji | F9: Tidak diuji | G9: Tidak diuji | H9: Tidak diuji | I9: Tidak diuji | J9: Tidak diuji | K9: Tidak diuji | L9: Tidak diuji | M9: Tidak diuji
A10: Android 13 atau lebih baru (ponsel) | B10: Chrome | C10: Tidak diuji | D10: Tidak diuji | E10: Tidak diuji | F10: Tidak diuji | G10: Tidak diuji | H10: Tidak diuji | I10: Tidak diuji | J10: Tidak diuji | K10: Tidak diuji | L10: Tidak diuji | M10: Tidak diuji
A11: Android (ponsel, layar kecil < 360 px) | B11: Chrome | C11: Tidak diuji | D11: Tidak diuji | E11: Tidak diuji | F11: Tidak diuji | G11: Tidak diuji | H11: Tidak diuji | I11: Tidak diuji | J11: Tidak diuji | K11: Tidak diuji | L11: Tidak diuji | M11: Tidak diuji
A12: Android | B12: Samsung Internet | C12: Tidak diuji | D12: Tidak diuji | E12: Tidak diuji | F12: Tidak diuji | G12: Tidak diuji | H12: Tidak diuji | I12: Tidak diuji | J12: Tidak diuji | K12: Tidak diuji | L12: Tidak diuji | M12: Tidak diuji
A13: iPhone (iOS 17 atau lebih baru) | B13: Safari | C13: Tidak diuji | D13: Tidak diuji | E13: Tidak diuji | F13: Tidak diuji | G13: Tidak diuji | H13: Tidak diuji | I13: Tidak diuji | J13: Tidak diuji | K13: Tidak diuji | L13: Tidak diuji | M13: Tidak diuji
A14: iPhone | B14: Chrome | C14: Tidak diuji | D14: Tidak diuji | E14: Tidak diuji | F14: Tidak diuji | G14: Tidak diuji | H14: Tidak diuji | I14: Tidak diuji | J14: Tidak diuji | K14: Tidak diuji | L14: Tidak diuji | M14: Tidak diuji
A15: iPad | B15: Safari | C15: Tidak diuji | D15: Tidak diuji | E15: Tidak diuji | F15: Tidak diuji | G15: Tidak diuji | H15: Tidak diuji | I15: Tidak diuji | J15: Tidak diuji | K15: Tidak diuji | L15: Tidak diuji | M15: Tidak diuji
C16: Tidak diuji | D16: Tidak diuji | E16: Tidak diuji | F16: Tidak diuji | G16: Tidak diuji | H16: Tidak diuji | I16: Tidak diuji | J16: Tidak diuji | K16: Tidak diuji | L16: Tidak diuji | M16: Tidak diuji
C17: Tidak diuji | D17: Tidak diuji | E17: Tidak diuji | F17: Tidak diuji | G17: Tidak diuji | H17: Tidak diuji | I17: Tidak diuji | J17: Tidak diuji | K17: Tidak diuji | L17: Tidak diuji | M17: Tidak diuji
C18: Tidak diuji | D18: Tidak diuji | E18: Tidak diuji | F18: Tidak diuji | G18: Tidak diuji | H18: Tidak diuji | I18: Tidak diuji | J18: Tidak diuji | K18: Tidak diuji | L18: Tidak diuji | M18: Tidak diuji
C19: Tidak diuji | D19: Tidak diuji | E19: Tidak diuji | F19: Tidak diuji | G19: Tidak diuji | H19: Tidak diuji | I19: Tidak diuji | J19: Tidak diuji | K19: Tidak diuji | L19: Tidak diuji | M19: Tidak diuji
C20: Tidak diuji | D20: Tidak diuji | E20: Tidak diuji | F20: Tidak diuji | G20: Tidak diuji | H20: Tidak diuji | I20: Tidak diuji | J20: Tidak diuji | K20: Tidak diuji | L20: Tidak diuji | M20: Tidak diuji
A22: Jumlah Lulus | C22: =COUNTIF(C5:C20,"Lulus") -> 0 | D22: =COUNTIF(D5:D20,"Lulus") -> 0 | E22: =COUNTIF(E5:E20,"Lulus") -> 0 | F22: =COUNTIF(F5:F20,"Lulus") -> 0 | G22: =COUNTIF(G5:G20,"Lulus") -> 0 | H22: =COUNTIF(H5:H20,"Lulus") -> 0 | I22: =COUNTIF(I5:I20,"Lulus") -> 0 | J22: =COUNTIF(J5:J20,"Lulus") -> 0 | ... M22: =COUNTIF(M5:M20,"Lulus") -> 0
A23: Jumlah Gagal | C23: =COUNTIF(C5:C20,"Gagal") -> 0 | D23: =COUNTIF(D5:D20,"Gagal") -> 0 | E23: =COUNTIF(E5:E20,"Gagal") -> 0 | F23: =COUNTIF(F5:F20,"Gagal") -> 0 | G23: =COUNTIF(G5:G20,"Gagal") -> 0 | H23: =COUNTIF(H5:H20,"Gagal") -> 0 | I23: =COUNTIF(I5:I20,"Gagal") -> 0 | J23: =COUNTIF(J5:J20,"Gagal") -> 0 | ... M23: =COUNTIF(M5:M20,"Gagal") -> 0
A25: Catatan: perangkat tanpa fitur tertentu (mis. komputer tanpa mikrofon untuk Ngobrol AI suara) diisi "Tidak berlaku".

Sheet QC Rilis
A1: QC sebelum rilis
A2: Item bertanda Wajib = Ya harus Lulus (atau Tidak berlaku dengan alasan) sebelum rilis. Dua item pertama di bagian Pengujian terisi otomatis dari lembar Ringkasan.
A3: Rilis / versi | E3: Item wajib yang belum Lulus | F3: =COUNTIFS(D12:D41,"Ya",F12:F41,"<>Lulus",F12:F41,"<>Tidak berlaku") -> 24
A4: Tanggal keputusan | E4: Item Gagal | F4: =COUNTIF(F12:F41,"Gagal") -> 0
A5: Penguji utama | E5: Rekomendasi sementara | F5: =IF(F4>0,"BELUM LAYAK: ada item Gagal",IF(F3>0,"BELUM LENGKAP: "&F3&" item wajib belum Lulus","Semua item wajib Lulus")) -> BELUM LENGKAP: 24 item wajib belum Lulus
A6: Penyetuju
A7: Keputusan akhir | E7: Keputusan akhir tetap di tangan manusia; rumus di atas hanya membantu.
A11: No | B11: Kelompok | C11: Pemeriksaan | D11: Wajib | E11: Cara memeriksa / rujukan kasus | F11: Status | G11: Penanggung jawab | H11: Tanggal | I11: Catatan
A12: 1 | B12: Lingkungan dan rilis | C12: Versi (commit) yang diuji tercatat di lembar Lingkungan dan sama dengan yang akan dirilis | D12: Ya | E12: git rev-parse --short HEAD | F12: Belum
A13: 2 | B13: Lingkungan dan rilis | C13: Migrasi database berhasil dijalankan tanpa galat dan tidak ada perubahan skema yang belum dimigrasi | D13: Ya | E13: docs/DEPLOY.md; CI memeriksa migrasi | F13: Belum
A14: 3 | B14: Lingkungan dan rilis | C14: Seluruh variabel lingkungan wajib terisi dan rahasia kuat (JWT, database, CORS_ORIGIN_*), tidak memakai contoh bawaan | D14: Ya | E14: docs/DEPLOY.md bagian konfigurasi | F14: Belum
A15: 4 | B15: Lingkungan dan rilis | C15: HTTPS aktif, HTTP dialihkan, sertifikat sah | D15: Ya | E15: TC-NF-01 | F15: Belum
A16: 5 | B16: Lingkungan dan rilis | C16: Jam server benar dan zona waktu (TZ) sesuai kebutuhan | D16: Ya | E16: TC-API-05, TC-NF-15 | F16: Belum
A17: 6 | B17: Lingkungan dan rilis | C17: Cadangan database terbaru ada dan pernah berhasil dipulihkan di lingkungan uji | D17: Ya | E17: TC-NF-14 | F17: Belum
A18: 7 | B18: Lingkungan dan rilis | C18: Alamat di tautan undangan dan reset password menunjuk ke aplikasi murid yang benar | D18: Ya | E18: TC-AD-30 | F18: Belum
A19: 8 | B19: Pengujian | C19: Semua kasus uji prioritas P1 sudah dijalankan dan lulus (tidak ada Gagal atau Belum diuji) | D19: Ya | E19: Lembar Ringkasan (otomatis) | F19: =IF(AND(Ringkasan!B36=0,Ringkasan!B37=0),"Lulus",IF(Ringkasan!B36>0,"Gagal","Belum")) -> Belum | G19: Otomatis
A20: 9 | B20: Pengujian | C20: Tidak ada bug Kritis atau Tinggi yang masih terbuka | D20: Ya | E20: Lembar Ringkasan (otomatis) | F20: =IF(AND(Ringkasan!B38=0,Ringkasan!B39=0),"Lulus","Gagal") -> Lulus | G20: Otomatis
A21: 10 | B21: Pengujian | C21: Uji asap API lulus penuh (npm run test:api, dan --lengkap di lingkungan uji) | D21: Ya | E21: TC-API-01 sampai TC-API-26 | F21: Belum
A22: 11 | B22: Pengujian | C22: Uji browser otomatis lulus tanpa kegagalan baru (npm test) | D22: Ya | E22: qa/README.md | F22: Belum
A23: 12 | B23: Pengujian | C23: Pemindaian aksesibilitas otomatis tidak melaporkan pelanggaran serius/kritis baru | D23: Ya | E23: TC-AX-01 sampai TC-AX-03 | F23: Belum
A24: 13 | B24: Alur inti manual | C24: Undangan dibuat admin, murid mendaftar, lulus pelajaran pertama, XP dan Leaderboard benar | D24: Ya | E24: TC-AK-01, TC-PL-10, TC-NL-02, TC-AD-14 | F24: Belum
A25: 14 | B25: Alur inti manual | C25: Lupa password sampai bisa masuk dengan password baru | D25: Ya | E25: TC-AK-18 | F25: Belum
A26: 15 | B26: Alur inti manual | C26: Percakapan skenario mode Latihan dan Tes, termasuk XP satu kali | D26: Ya | E26: TC-PC-04 sampai TC-PC-08 | F26: Belum
A27: 16 | B27: Alur inti manual | C27: Ngobrol dengan AI: kirim pesan, jatah berkurang, pesan galat jelas bila AI mati atau jatah habis | D27: Tidak | E27: TC-AI-09, TC-AI-14, TC-AI-15 (hanya bila AI dipakai di rilis ini) | F27: Belum
A28: 17 | B28: Alur inti manual | C28: Admin: kelas, undangan, murid, pindah kelas, nonaktifkan/aktifkan | D28: Ya | E28: TC-AD-10 sampai TC-AD-28 | F28: Belum
A29: 18 | B29: Keamanan | C29: Pemisahan hak akses murid/admin, field terlarang ditolak, data pribadi tidak bocor | D29: Ya | E29: TC-API-19, TC-NF-06 sampai TC-NF-08 | F29: Belum
A30: 19 | B30: Keamanan | C30: Dokumentasi API tidak terbuka ke publik; CORS hanya untuk asal resmi; header keamanan terpasang | D30: Ya | E30: TC-NF-02 sampai TC-NF-04 | F30: Belum
A31: 20 | B31: Keamanan | C31: Pembatas permintaan aktif dan pengguna di jaringan bersama tidak terkunci sia-sia | D31: Ya | E31: TC-NF-05 | F31: Belum
A32: 21 | B32: Keamanan | C32: Keputusan atas temuan awal: Keluar tidak mencabut sesi, murid nonaktif tetap punya sesi, XP Tes pada percobaan gagal | D32: Ya | E32: Lembar Temuan Awal; TC-AK-24, TC-AD-27, TC-PC-08 | F32: Belum
... A39: 28 | B39: Kinerja | C39: Beranda termuat wajar di jaringan seluler dan beban ringan tidak menimbulkan galat | D39: Tidak | E39: TC-NF-10, TC-NF-11 | F39: Belum
A40: 29 | B40: Dokumentasi | C40: Catatan rilis, daftar bug terbuka yang diketahui, dan perubahan penting sudah ditulis dan dibagikan | D40: Ya | F40: Belum
A41: 30 | B41: Dokumentasi | C41: Panduan pengguna/admin dan docs/DEPLOY.md sesuai dengan versi yang dirilis | D41: Tidak | E41: docs/DEPLOY.md, README.md | F41: Belum

Sheet Cakupan Fitur
A1: Cakupan fitur oleh kasus uji
A2: Dipetakan dari dokumen Daftar Fitur Rinci (6 Oktober 2026). Fitur berstatus Belum dibangun hanya diperiksa agar tidak tampil/menjanjikan (TC-BT-01).
A4: Kode | B4: Fitur | C4: Kelompok | D4: Status | E4: Jumlah kasus | F4: Kasus uji terkait
A5: AK-01 | B5: Pendaftaran lewat undangan | C5: Murid: Akun dan masuk | D5: Tersedia | E5: =COUNTIF('Kasus Uji'!$J$5:$J$264,"*"&$A5&"*") -> 3 | F5: TC-AK-01, TC-AK-02, TC-AK-03
A6: AK-02 | B6: Tautan undangan bermasalah | C6: Murid: Akun dan masuk | D6: Sebagian | E6: =COUNTIF('Kasus Uji'!$J$5:$J$264,"*"&$A6&"*") -> 3 | F6: TC-AK-04, TC-AK-05, TC-AK-06
A7: AK-03 | B7: Pengenalan awal | C7: Murid: Akun dan masuk | D7: Tersedia | E7: =COUNTIF('Kasus Uji'!$J$5:$J$264,"*"&$A7&"*") -> 2 | F7: TC-AK-01, TC-AK-07
A8: AK-04 | B8: Masuk | C8: Murid: Akun dan masuk | D8: Tersedia | E8: =COUNTIF('Kasus Uji'!$J$5:$J$264,"*"&$A8&"*") -> 20 | F8: TC-AK-08, TC-AK-09, TC-AK-10, TC-AK-11, TC-AK-12, TC-AK-13, TC-AK-14, TC-AK-22, TC-AK-23, TC-AK-27, TC-AK-28, TC-AK-29, TC-AD-27, TC-API-05, TC-API-06, TC-API-07, TC-API-08, TC-API-23, TC-API-25, TC-NF-12
A9: AK-05 | B9: Penguncian akun | C9: Murid: Akun dan masuk | D9: Tersedia | E9: =COUNTIF('Kasus Uji'!$J$5:$J$264,"*"&$A9&"*") -> 3 | F9: TC-AK-15, TC-AK-26, TC-NF-13
A10: AK-06 | B10: Lupa password | C10: Murid: Akun dan masuk | D10: Sebagian | E10: =COUNTIF('Kasus Uji'!$J$5:$J$264,"*"&$A10&"*") -> 5 | F10: TC-AK-16, TC-AK-17, TC-AD-30, TC-API-24, TC-AK-31
A11: AK-07 | B11: Membuat password baru | C11: Murid: Akun dan masuk | D11: Tersedia | E11: =COUNTIF('Kasus Uji'!$J$5:$J$264,"*"&$A11&"*") -> 5 | F11: TC-AK-18, TC-AK-19, TC-AK-20, TC-AK-25, TC-AK-26
A12: AK-08 | B12: Keluar | C12: Murid: Akun dan masuk | D12: Tersedia | E12: =COUNTIF('Kasus Uji'!$J$5:$J$264,"*"&$A12&"*") -> 3 | F12: TC-AK-21, TC-AK-24, TC-AK-30
A13: AK-09 | B13: Penempatan kelas otomatis | C13: Murid: Akun dan masuk | D13: Tersedia | E13: =COUNTIF('Kasus Uji'!$J$5:$J$264,"*"&$A13&"*") -> 2 | F13: TC-AK-01, TC-AD-25
A14: AK-10 | B14: Email otomatis dari aplikasi | C14: Murid: Akun dan masuk | D14: Belum | E14: =COUNTIF('Kasus Uji'!$J$5:$J$264,"*"&$A14&"*") -> 1 | F14: TC-AK-31
A15: AK-11 | B15: Tes penempatan level | C15: Murid: Akun dan masuk | D15: Belum | E15: =COUNTIF('Kasus Uji'!$J$5:$J$264,"*"&$A15&"*") -> 1 | F15: TC-BT-01
A16: BR-01 | B16: Ringkasan di Beranda | C16: Murid: Beranda dan jalur belajar | D16: Tersedia | E16: =COUNTIF('Kasus Uji'!$J$5:$J$264,"*"&$A16&"*") -> 2 | F16: TC-BR-01, TC-BR-12
... A115: KN-02 | B115: Pemeriksaan salah ketik | C115: Admin: Pelajaran baru dari dokumen Word | D115: Tersedia | E115: =COUNTIF('Kasus Uji'!$J$5:$J$264,"*"&$A115&"*") -> 1 | F115: TC-KT-11
B117: Jumlah fitur | E117: =COUNTA(A5:A115) -> 111
B118: Tersedia | E118: =COUNTIF(D5:D115,"Tersedia") -> 70
B119: Sebagian | E119: =COUNTIF(D5:D115,"Sebagian") -> 22
B120: Belum dibangun | E120: =COUNTIF(D5:D115,"Belum") -> 19
B121: Tersedia atau sebagian TANPA kasus uji (harus 0) | E121: =COUNTIFS(D5:D115,"<>Belum",E5:E115,0) -> 0

Sheet Data Uji
A1: Data uji
A2: Contoh isian untuk uji batas dan alat bantu hitung. Sel biru = angka yang boleh diubah (masukan); sel abu-abu = hasil rumus.
A4: A. Kalkulator ambang lulus pelajaran (untuk TC-NL-04)
A5: Jumlah soal pelajaran | B5: 19 | C5: Ubah sesuai pelajaran yang diuji (tabel jumlah soal di bawah). Lulus bila akurasi 80% atau lebih; bintang 80-89 = 1, 90-99 = 2, 100 = 3; XP pertama kali lulus 10/20/30 (checkpoint 50).
A7: Jumlah jawaban salah | B7: Total jawaban (soal + salah) | C7: Akurasi (%) | D7: Hasil | E7: Bintang | F7: XP pelajaran biasa
A8: 0 | B8: =$B$5+A8 -> 19 | C8: =ROUND($B$5/B8*100,0) -> 100 | D8: =IF(C8>=80,"Lulus","Belum Lulus") -> Lulus | E8: =IF(C8<80,0,IF(C8=100,3,IF(C8>=90,2,1))) -> 3 | F8: =CHOOSE(E8+1,0,10,20,30) -> 30
A9: 1 | B9: =$B$5+A9 -> 20 | C9: =ROUND($B$5/B9*100,0) -> 95 | D9: =IF(C9>=80,"Lulus","Belum Lulus") -> Lulus | E9: =IF(C9<80,0,IF(C9=100,3,IF(C9>=90,2,1))) -> 2 | F9: =CHOOSE(E9+1,0,10,20,30) -> 20
A10: 2 | B10: =$B$5+A10 -> 21 | C10: =ROUND($B$5/B10*100,0) -> 90 | D10: =IF(C10>=80,"Lulus","Belum Lulus") -> Lulus | E10: =IF(C10<80,0,IF(C10=100,3,IF(C10>=90,2,1))) -> 2 | F10: =CHOOSE(E10+1,0,10,20,30) -> 20
A11: 3 | B11: =$B$5+A11 -> 22 | C11: =ROUND($B$5/B11*100,0) -> 86 | D11: =IF(C11>=80,"Lulus","Belum Lulus") -> Lulus | E11: =IF(C11<80,0,IF(C11=100,3,IF(C11>=90,2,1))) -> 1 | F11: =CHOOSE(E11+1,0,10,20,30) -> 10
A12: 4 | B12: =$B$5+A12 -> 23 | C12: =ROUND($B$5/B12*100,0) -> 83 | D12: =IF(C12>=80,"Lulus","Belum Lulus") -> Lulus | E12: =IF(C12<80,0,IF(C12=100,3,IF(C12>=90,2,1))) -> 1 | F12: =CHOOSE(E12+1,0,10,20,30) -> 10
A13: 5 | B13: =$B$5+A13 -> 24 | C13: =ROUND($B$5/B13*100,0) -> 79 | D13: =IF(C13>=80,"Lulus","Belum Lulus") -> Belum Lulus | E13: =IF(C13<80,0,IF(C13=100,3,IF(C13>=90,2,1))) -> 0 | F13: =CHOOSE(E13+1,0,10,20,30) -> 0
A14: 6 | B14: =$B$5+A14 -> 25 | C14: =ROUND($B$5/B14*100,0) -> 76 | D14: =IF(C14>=80,"Lulus","Belum Lulus") -> Belum Lulus | E14: =IF(C14<80,0,IF(C14=100,3,IF(C14>=90,2,1))) -> 0 | F14: =CHOOSE(E14+1,0,10,20,30) -> 0
A15: 7 | B15: =$B$5+A15 -> 26 | C15: =ROUND($B$5/B15*100,0) -> 73 | D15: =IF(C15>=80,"Lulus","Belum Lulus") -> Belum Lulus | E15: =IF(C15<80,0,IF(C15=100,3,IF(C15>=90,2,1))) -> 0 | F15: =CHOOSE(E15+1,0,10,20,30) -> 0
A16: 8 | B16: =$B$5+A16 -> 27 | C16: =ROUND($B$5/B16*100,0) -> 70 | D16: =IF(C16>=80,"Lulus","Belum Lulus") -> Belum Lulus | E16: =IF(C16<80,0,IF(C16=100,3,IF(C16>=90,2,1))) -> 0 | F16: =CHOOSE(E16+1,0,10,20,30) -> 0
A18: B. Jumlah soal tiap pelajaran (data saat kit dibuat)
A19: Pelajaran (ID) | B19: Jumlah soal | C19: Soal pilih | D19: Soal susun
A20: l1 Baris a, ka, sa | B20: 19 | C20: 15 | D20: 4
A21: l2 Baris ta, na, ha | B21: 19 | C21: 15 | D21: 4
A22: l3 Baris ma, ya, ra, wa, n | B22: 20 | C22: 16 | D22: 4
A23: l4 Dakuten: ga, za, da | B23: 19 | C23: 15 | D23: 4
A24: l5 Dakuten ba dan handakuten pa | B24: 14 | C24: 10 | D24: 4
A25: l6 Youon 1 | B25: 16 | C25: 12 | D25: 4
A26: l7 Youon 2, sokuon, vokal panjang | B26: 21 | C26: 21 | D26: 0
A27: k3_l1 sampai k3_l11 (Unit 3) | B27: 21 sampai 29 | C27: - | D27: -
A29: C. Isian teks untuk uji batas
A30: Jenis | B30: Nilai uji | G30: Yang diperiksa
A31: Nama | B31: (kosong) | G31: Ditolak dengan pesan jelas.
A32: Nama | B32: (spasi saja) | G32: Ditolak: "Nama tidak boleh kosong.".
A33: Nama | B33: A | G33: Diterima (1 karakter).
A34: Nama | B34: 田中 さくら Ani | G34: Huruf Jepang dan Latin tampil benar di semua halaman.
A35: Nama | B35: Ani 😀 Sari | G35: Emoji tidak merusak tampilan atau tersimpan sebagai tanda tanya.
A36: Nama | B36: <script>alert(1)</script> | G36: Tampil sebagai teks, tidak dijalankan.
A37: Nama | B37: ' OR 1=1 -- | G37: Tersimpan sebagai teks biasa.
A38: Nama | B38: (300 karakter: Bu diulang 150 kali) | G38: Tidak merusak tata letak; server saat ini tidak membatasi panjang.
A39: Email | B39: nama@contoh.id | G39: Valid.
A40: Email | B40: NAMA@Contoh.ID | G40: Dianggap sama dengan huruf kecil.
A41: Email | B41: nama@ | G41: Ditolak oleh browser/server.
... A54: Skenario Perkenalan Diri (jawaban benar) | B54: Baris 1: はじめまして。よろしくお願いします。 | Baris 2: わたしの名前はアニです。 | G54: Dipakai untuk TC-PC-07.

Sheet Temuan Awal
A1: Temuan awal saat menyusun buku ini
A2: Dari membaca kode dan menjalankan aplikasi di lingkungan pengembangan (bukan di server penguji). Ini bahan keputusan pemilik produk, bukan bug yang sudah dikonfirmasi di server Anda: konfirmasi dulu lewat kasus uji terkait.
A4: No | B4: Area | C4: Temuan | D4: Dampak | E4: Kasus uji terkait | F4: Tingkat | G4: Saran atau keputusan yang dibutuhkan
